<?xml version="1.0" ?>
<mujoco>
  <worldbody>
    <geom name="plane" type="plane" size="1 1 0.02" rgba="0.9 0.9 0.9 1"/>
    <body name="subbody0">
      <body name="sphere0" pos="0 0 0">
        <geom name="geom0" type="sphere" size="0.1" rgba="1 0 0 1"/>
      </body>
      <body name="subbody1">
        <body name="sphere1" pos="0.5527927898108473 -0.6114098691420309 0.6491074361467932">
          <geom name="geom1" type="sphere" size="0.1" rgba="1 0 0 1"/>
        </body>
        <joint name="joint_subbody1_subbody0" type="ball" limited="false"/>
      </body>
    </body>
  </worldbody>
</mujoco>