<?xml version="1.0" ?>
<mujoco>
	<option gravity="0 0 -9.81"/>
	<worldbody>
		<light diffuse=".5 .5 .5" pos="0 0 3" dir="0 0 -1"/>
		<geom type="plane" size="10 10 0.1" rgba=".9 0 0 1"/>
		<body pos="0 0 0.1">
			<joint type="free"/>
			<geom size="0.1" type="sphere" rgba="0 0 1 1" pos="0.1 0 0"/>
			<site name="site0" pos="0.1 0 0" size="0.1" rgba="1 0 0 1"/>
			<body pos="0.2 0 0">
				<joint name="joint1" type="ball" limited="true" range="0 60"/>
				<geom size="0.1" rgba="0 0 1 1" pos="0.1 0 0"/>
				<site name="site1" pos="0.1 0 0" size="0.1" rgba="1 0 0 1"/>
				<body pos="0.2 0 0">
					<joint name="joint2" type="ball" limited="true" range="0 60"/>
					<geom size="0.1" rgba="0 0 1 1" pos="0.1 0 0"/>
					<site name="site2" pos="0.1 0 0" size="0.1" rgba="1 0 0 1"/>
					<body pos="0.2 0 0">
						<joint name="joint3" type="ball" limited="true" range="0 60"/>
						<geom size="0.1" rgba="0 0 1 1" pos="0.1 0 0"/>
						<site name="site3" pos="0.1 0 0" size="0.1" rgba="1 0 0 1"/>
					</body>
				</body>
			</body>
		</body>
	</worldbody>
	<actuator>
		<motor name="motor1" joint="joint1" gear="10"/>
		<motor name="motor2" joint="joint2" gear="10"/>
		<motor name="motor3" joint="joint3" gear="10"/>
	</actuator>
	<sensor>
		<touch name="test0" site="site0"/>
		<touch name="test1" site="site1"/>
		<touch name="test2" site="site2"/>
		<touch name="test3" site="site3"/>
	</sensor>
</mujoco>
